Workbook

Sheet DASHBOARD

Sheet DASHBOARDMoM

Sheet DASHBOARDYoY

Sheet PIVOT GENERAL
A3: Average of FoodBucket | B3: Average of General index | C3: Average of Housingbucket | D3: Average of MiscellaneousBucket | E3: Average of Oils and fatsBuckets | F3: Average of Clothing and footwearbucket | G3: Average of Pantobaccobuckets
A4: 1690.752 | B4: 137.31344 | C4: 92.08871 | D4: 1066.1812 | E4: 131.06075 | F4: 413.53602 | G4: 152.87957
A8: Year | B8: AvgYoY
A9: 2013 | B9: 110.01389
A10: 2014 | B10: 117.32778
A11: 2015 | B11: 123.03611
A12: 2016 | B12: 129.1
A13: 2017 | B13: 133.38611
A14: 2018 | B14: 138.66944
A15: 2019 | B15: 144.12727
A16: 2020 | B16: 127.775
A17: 2021 | B17: 161.41667
A18: 2022 | B18: 172.075
A19: 2023 | B19: 177.57333
A20: Grand Total | B20: 137.31344
D22: Row Labels | E22: Sum of FoodBucket | F22: Sum of Housingbucket | G22: Sum of MiscellaneousBucket | H22: Sum of Oils and fatsBuckets | I22: Sum of Pantobaccobuckets | J22: Sum of Clothing and footwearbucket
D23: Rural | E23: 206955 | F23: 0 | G23: 134554.2 | H23: 16751.4 | I23: 18750.1 | J23: 52855.9
D24: Rural+Urban | E24: 207686.1 | F24: 17128.8 | G24: 132264.3 | H24: 16350.6 | I24: 18882.2 | J24: 51495.8
D25: Urban | E25: 209246.4 | F25: 17128.2 | G25: 129800.9 | H25: 15652.6 | I25: 19238.9 | J25: 49483.7

Sheet cpiassignment
A1: Sector | B1: Year | C1: Month | D1: Month Number | E1: Date | F1: Cereals and products | G1: Meat and fish | H1: Egg | I1: Milk and products | J1: Oils and fats | K1: Fruits | L1: Vegetables | M1: Pulses and products | N1: Sugar and Confectionery | O1: Spices | P1: Non-alcoholic beverages | Q1: Prepared meals, snacks, sweets etc. | R1: Food and beverages | S1: Pan, tobacco and intoxicants | T1: Clothing | U1: Footwear | V1: Clothing and footwear | W1: Housing | X1: Fuel and light | Y1: Household goods and services | Z1: Health | AA1: Transport and communication | AB1: Recreation and amusement | AC1: Education | AD1: Personal care and effects | AE1: Miscellaneous | AF1: General index | AG1: FoodBucket | AH1: Housingbucket | AI1: MiscellaneousBucket | AJ1: Oils and fatsBuckets | AK1: Pantobaccobuckets | AL1: Clothing and footwearbucket | AM1: CRUID BUCKET | AN1: COVID_Period | AO1: Flag | AP1: CountflagNo | AQ1: Date 1 | AR1: COVID_Period1 | AS1: monthnumber1
A2: Rural | B2: 2013 | C2: january | D2: 1 | E2: 41275 | F2: 107.5 | G2: 106.3 | H2: 108.1 | I2: 104.9 | J2: 106.1 | K2: 103.9 | L2: 101.9 | M2: 106.1 | N2: 106.8 | O2: 103.1 | P2: 104.8 | Q2: 106.7 | R2: 105.5 | S2: 105.1 | T2: 106.5 | U2: 105.8 | V2: 106.4 | W2: 0 | X2: 105.5 | Y2: 104.8 | Z2: 104 | AA2: 103.3 | AB2: 103.4 | AC2: 103.8 | AD2: 104.7 | AE2: 104 | AF2: 105.1 | AG2: 1265.6 | AH2: 0 | AI2: 834.6 | AJ2: 106.1 | AK2: 105.1 | AL2: 318.7 | AM2: =VLOOKUP(E2,CRUIDdata!C:D,2,FALSE) -> 94 | AN2: Pre-COVID | AO2: =IF(AND(K2>150,L2>150),"no") -> FALSE | AP2: =COUNTIF(AO:AO,"no") -> 91 | AQ2: =DATE(B2,MONTH(1&TRIM(C2)),1) -> 41275 | AR2: =IF(E2<DATE(2020,3,1),"Pre-COVID","Post-COVID") -> Pre-COVID | AS2: =MONTH(DATEVALUE("1 "& C2)) -> 1
A3: Urban | B3: 2013 | C3: january | D3: 1 | E3: 41275 | F3: 110.5 | G3: 109.1 | H3: 113 | I3: 103.6 | J3: 103.4 | K3: 102.3 | L3: 102.9 | M3: 105.8 | N3: 105.1 | O3: 101.8 | P3: 105.1 | Q3: 107.9 | R3: 105.9 | S3: 105.2 | T3: 105.9 | U3: 105 | V3: 105.8 | W3: 100.3 | X3: 105.4 | Y3: 104.8 | Z3: 104.1 | AA3: 103.2 | AB3: 102.9 | AC3: 103.5 | AD3: 104.3 | AE3: 103.7 | AF3: 104 | AG3: 1273 | AH3: 100.3 | AI3: 831.8 | AJ3: 103.4 | AK3: 105.2 | AL3: 316.7 | AM3: =VLOOKUP(E3,CRUIDdata!C:D,2,FALSE) -> 94 | AN3: Pre-COVID | AO3: =IF(AND(K3>150,L3>150),"no") -> FALSE | AQ3: =DATE(B3,MONTH(1&TRIM(C3)),1) -> 41275 | AR3: =IF(E3<DATE(2020,3,1),"Pre-COVID","Post-COVID") -> Pre-COVID | AS3: =MONTH(DATEVALUE("1 "& C3)) -> 1
A4: Rural+Urban | B4: 2013 | C4: january | D4: 1 | E4: 41275 | F4: 108.4 | G4: 107.3 | H4: 110 | I4: 104.4 | J4: 105.1 | K4: 103.2 | L4: 102.2 | M4: 106 | N4: 106.2 | O4: 102.7 | P4: 104.9 | Q4: 107.3 | R4: 105.6 | S4: 105.1 | T4: 106.3 | U4: 105.5 | V4: 106.2 | W4: 100.3 | X4: 105.5 | Y4: 104.8 | Z4: 104 | AA4: 103.2 | AB4: 103.1 | AC4: 103.6 | AD4: 104.5 | AE4: 103.9 | AF4: 104.6 | AG4: 1268.2 | AH4: 100.3 | AI4: 833.2 | AJ4: 105.1 | AK4: 105.1 | AL4: 318 | AM4: =VLOOKUP(E4,CRUIDdata!C:D,2,FALSE) -> 94 | AN4: Pre-COVID | AO4: =IF(AND(K4>150,L4>150),"no") -> FALSE | AQ4: =DATE(B4,MONTH(1&TRIM(C4)),1) -> 41275 | AR4: =IF(E4<DATE(2020,3,1),"Pre-COVID","Post-COVID") -> Pre-COVID | AS4: =MONTH(DATEVALUE("1 "& C4)) -> 1
A5: Rural | B5: 2013 | C5: february | D5: 2 | E5: 41306 | F5: 109.2 | G5: 108.7 | H5: 110.2 | I5: 105.4 | J5: 106.7 | K5: 104 | L5: 102.4 | M5: 105.9 | N5: 105.7 | O5: 103.1 | P5: 105.1 | Q5: 107.7 | R5: 106.3 | S5: 105.6 | T5: 107.1 | U5: 106.3 | V5: 107 | W5: 0 | X5: 106.2 | Y5: 105.2 | Z5: 104.4 | AA5: 103.9 | AB5: 104 | AC5: 104.1 | AD5: 104.6 | AE5: 104.4 | AF5: 105.8 | AG5: 1273.7 | AH5: 0 | AI5: 838.2 | AJ5: 106.7 | AK5: 105.6 | AL5: 320.4 | AM5: =VLOOKUP(E5,CRUIDdata!C:D,2,FALSE) -> 95 | AN5: Pre-COVID | AO5: =IF(AND(K5>150,L5>150),"no") -> FALSE | AQ5: =DATE(B5,MONTH(1&TRIM(C5)),1) -> 41306 | AR5: =IF(E5<DATE(2020,3,1),"Pre-COVID","Post-COVID") -> Pre-COVID | AS5: =MONTH(DATEVALUE("1 "& C5)) -> 2
A6: Urban | B6: 2013 | C6: february | D6: 2 | E6: 41306 | F6: 112.9 | G6: 112.9 | H6: 116.9 | I6: 104 | J6: 103.5 | K6: 103.1 | L6: 104.9 | M6: 104.1 | N6: 103.8 | O6: 102.3 | P6: 106 | Q6: 109 | R6: 107.2 | S6: 106 | T6: 106.6 | U6: 105.5 | V6: 106.4 | W6: 100.4 | X6: 105.7 | Y6: 105.2 | Z6: 104.7 | AA6: 104.4 | AB6: 103.3 | AC6: 103.7 | AD6: 104.3 | AE6: 104.3 | AF6: 104.7 | AG6: 1287.1 | AH6: 100.4 | AI6: 835.6 | AJ6: 103.5 | AK6: 106 | AL6: 318.5 | AM6: =VLOOKUP(E6,CRUIDdata!C:D,2,FALSE) -> 95 | AN6: Pre-COVID | AO6: =IF(AND(K6>150,L6>150),"no") -> FALSE | AQ6: =DATE(B6,MONTH(1&TRIM(C6)),1) -> 41306 | AR6: =IF(E6<DATE(2020,3,1),"Pre-COVID","Post-COVID") -> Pre-COVID | AS6: =MONTH(DATEVALUE("1 "& C6)) -> 2
A7: Rural+Urban | B7: 2013 | C7: february | D7: 2 | E7: 41306 | F7: 110.4 | G7: 110.2 | H7: 112.8 | I7: 104.9 | J7: 105.5 | K7: 103.6 | L7: 103.2 | M7: 105.3 | N7: 105.1 | O7: 102.8 | P7: 105.5 | Q7: 108.3 | R7: 106.6 | S7: 105.7 | T7: 106.9 | U7: 106 | V7: 106.8 | W7: 100.4 | X7: 106 | Y7: 105.2 | Z7: 104.5 | AA7: 104.2 | AB7: 103.6 | AC7: 103.9 | AD7: 104.5 | AE7: 104.4 | AF7: 105.3 | AG7: 1278.7 | AH7: 100.4 | AI7: 837.1 | AJ7: 105.5 | AK7: 105.7 | AL7: 319.7 | AM7: =VLOOKUP(E7,CRUIDdata!C:D,2,FALSE) -> 95 | AN7: Pre-COVID | AO7: =IF(AND(K7>150,L7>150),"no") -> FALSE | AQ7: =DATE(B7,MONTH(1&TRIM(C7)),1) -> 41306 | AR7: =IF(E7<DATE(2020,3,1),"Pre-COVID","Post-COVID") -> Pre-COVID | AS7: =MONTH(DATEVALUE("1 "& C7)) -> 2
A8: Rural | B8: 2013 | C8: march | D8: 3 | E8: 41334 | F8: 110.2 | G8: 108.8 | H8: 109.9 | I8: 105.6 | J8: 106.2 | K8: 105.7 | L8: 101.4 | M8: 105.7 | N8: 105 | O8: 103.3 | P8: 105.6 | Q8: 108.2 | R8: 106.6 | S8: 106.5 | T8: 107.6 | U8: 106.8 | V8: 107.5 | W8: 0 | X8: 106.1 | Y8: 105.6 | Z8: 104.7 | AA8: 104.6 | AB8: 104 | AC8: 104.3 | AD8: 104.3 | AE8: 104.6 | AF8: 106 | AG8: 1276 | AH8: 0 | AI8: 839.5 | AJ8: 106.2 | AK8: 106.5 | AL8: 321.9 | AM8: =VLOOKUP(E8,CRUIDdata!C:D,2,FALSE) -> 92 | AN8: Pre-COVID | AO8: =IF(AND(K8>150,L8>150),"no") -> FALSE | AQ8: =DATE(B8,MONTH(1&TRIM(C8)),1) -> 41334 | AR8: =IF(E8<DATE(2020,3,1),"Pre-COVID","Post-COVID") -> Pre-COVID | AS8: =MONTH(DATEVALUE("1 "& C8)) -> 3
A9: Urban | B9: 2013 | C9: march | D9: 3 | E9: 41334 | F9: 113.9 | G9: 111.4 | H9: 113.2 | I9: 104.3 | J9: 102.7 | K9: 104.9 | L9: 103.8 | M9: 103.5 | N9: 102.6 | O9: 102.4 | P9: 107 | Q9: 109.8 | R9: 107.3 | S9: 106.8 | T9: 107.2 | U9: 106 | V9: 107 | W9: 100.4 | X9: 106 | Y9: 105.7 | Z9: 105.2 | AA9: 105.5 | AB9: 103.5 | AC9: 103.8 | AD9: 104.2 | AE9: 104.9 | AF9: 105 | AG9: 1284.1 | AH9: 100.4 | AI9: 838.6 | AJ9: 102.7 | AK9: 106.8 | AL9: 320.2 | AM9: =VLOOKUP(E9,CRUIDdata!C:D,2,FALSE) -> 92 | AN9: Pre-COVID | AO9: =IF(AND(K9>150,L9>150),"no") -> FALSE | AQ9: =DATE(B9,MONTH(1&TRIM(C9)),1) -> 41334 | AR9: =IF(E9<DATE(2020,3,1),"Pre-COVID","Post-COVID") -> Pre-COVID | AS9: =MONTH(DATEVALUE("1 "& C9)) -> 3
A10: Rural+Urban | B10: 2013 | C10: march | D10: 3 | E10: 41334 | F10: 111.4 | G10: 109.7 | H10: 111.2 | I10: 105.1 | J10: 104.9 | K10: 105.3 | L10: 102.2 | M10: 105 | N10: 104.2 | O10: 103 | P10: 106.2 | Q10: 108.9 | R10: 106.9 | S10: 106.6 | T10: 107.4 | U10: 106.5 | V10: 107.3 | W10: 100.4 | X10: 106.1 | Y10: 105.6 | Z10: 104.9 | AA10: 105.1 | AB10: 103.7 | AC10: 104 | AD10: 104.3 | AE10: 104.7 | AF10: 105.5 | AG10: 1279.1 | AH10: 100.4 | AI10: 839 | AJ10: 104.9 | AK10: 106.6 | AL10: 321.2 | AM10: =VLOOKUP(E10,CRUIDdata!C:D,2,FALSE) -> 92 | AN10: Pre-COVID | AO10: =IF(AND(K10>150,L10>150),"no") -> FALSE | AQ10: =DATE(B10,MONTH(1&TRIM(C10)),1) -> 41334 | AR10: =IF(E10<DATE(2020,3,1),"Pre-COVID","Post-COVID") -> Pre-COVID | AS10: =MONTH(DATEVALUE("1 "& C10)) -> 3
A11: Rural | B11: 2013 | C11: april | D11: 4 | E11: 41365 | F11: 110.2 | G11: 109.5 | H11: 106.9 | I11: 106.3 | J11: 105.7 | K11: 108.3 | L11: 103.4 | M11: 105.7 | N11: 104.2 | O11: 103.2 | P11: 106.5 | Q11: 108.8 | R11: 107.1 | S11: 107.1 | T11: 108.1 | U11: 107.4 | V11: 108 | W11: 0 | X11: 106.5 | Y11: 106.1 | Z11: 105.1 | AA11: 104.4 | AB11: 104.5 | AC11: 104.8 | AD11: 102.7 | AE11: 104.6 | AF11: 106.4 | AG11: 1280.1 | AH11: 0 | AI11: 840 | AJ11: 105.7 | AK11: 107.1 | AL11: 323.5 | AM11: =VLOOKUP(E11,CRUIDdata!C:D,2,FALSE) -> 91 | AN11: Pre-COVID | AO11: =IF(AND(K11>150,L11>150),"no") -> FALSE | AQ11: =DATE(B11,MONTH(1&TRIM(C11)),1) -> 41365 | AR11: =IF(E11<DATE(2020,3,1),"Pre-COVID","Post-COVID") -> Pre-COVID | AS11: =MONTH(DATEVALUE("1 "& C11)) -> 4
A12: Urban | B12: 2013 | C12: april | D12: 4 | E12: 41365 | F12: 114.6 | G12: 113.4 | H12: 106 | I12: 104.7 | J12: 102.1 | K12: 109.5 | L12: 109.7 | M12: 104.6 | N12: 102 | O12: 103.5 | P12: 108.2 | Q12: 110.6 | R12: 108.8 | S12: 108.5 | T12: 107.9 | U12: 106.4 | V12: 107.7 | W12: 100.5 | X12: 106.4 | Y12: 106.5 | Z12: 105.7 | AA12: 105 | AB12: 104 | AC12: 105.2 | AD12: 103.2 | AE12: 105.1 | AF12: 105.7 | AG12: 1295.6 | AH12: 100.5 | AI12: 841.1 | AJ12: 102.1 | AK12: 108.5 | AL12: 322 | AM12: =VLOOKUP(E12,CRUIDdata!C:D,2,FALSE) -> 91 | AN12: Pre-COVID | AO12: =IF(AND(K12>150,L12>150),"no") -> FALSE | AQ12: =DATE(B12,MONTH(1&TRIM(C12)),1) -> 41365 | AR12: =IF(E12<DATE(2020,3,1),"Pre-COVID","Post-COVID") -> Pre-COVID | AS12: =MONTH(DATEVALUE("1 "& C12)) -> 4
A13: Rural+Urban | B13: 2013 | C13: april | D13: 4 | E13: 41365 | F13: 111.6 | G13: 110.9 | H13: 106.6 | I13: 105.7 | J13: 104.4 | K13: 108.9 | L13: 105.5 | M13: 105.3 | N13: 103.5 | O13: 103.3 | P13: 107.2 | Q13: 109.6 | R13: 107.7 | S13: 107.5 | T13: 108 | U13: 107 | V13: 107.9 | W13: 100.5 | X13: 106.5 | Y13: 106.3 | Z13: 105.3 | AA13: 104.7 | AB13: 104.2 | AC13: 105 | AD13: 102.9 | AE13: 104.8 | AF13: 106.1 | AG13: 1285.8 | AH13: 100.5 | AI13: 840.5 | AJ13: 104.4 | AK13: 107.5 | AL13: 322.9 | AM13: =VLOOKUP(E13,CRUIDdata!C:D,2,FALSE) -> 91 | AN13: Pre-COVID | AO13: =IF(AND(K13>150,L13>150),"no") -> FALSE | AQ13: =DATE(B13,MONTH(1&TRIM(C13)),1) -> 41365 | AR13: =IF(E13<DATE(2020,3,1),"Pre-COVID","Post-COVID") -> Pre-COVID | AS13: =MONTH(DATEVALUE("1 "& C13)) -> 4
A14: Rural | B14: 2013 | C14: may | D14: 5 | E14: 41395 | F14: 110.9 | G14: 109.8 | H14: 105.9 | I14: 107.5 | J14: 105.3 | K14: 108.1 | L14: 107.3 | M14: 106.1 | N14: 103.7 | O14: 104 | P14: 107.4 | Q14: 109.9 | R14: 108.1 | S14: 108.1 | T14: 108.8 | U14: 107.9 | V14: 108.6 | W14: 0 | X14: 107.5 | Y14: 106.8 | Z14: 105.7 | AA14: 104.1 | AB14: 105 | AC14: 105.5 | AD14: 102.1 | AE14: 104.8 | AF14: 107.2 | AG14: 1288.7 | AH14: 0 | AI14: 843 | AJ14: 105.3 | AK14: 108.1 | AL14: 325.3 | AM14: =VLOOKUP(E14,CRUIDdata!C:D,2,FALSE) -> 93 | AN14: Pre-COVID | AO14: =IF(AND(K14>150,L14>150),"no") -> FALSE | AQ14: =DATE(B14,MONTH(1&TRIM(C14)),1) -> 41395 | AR14: =IF(E14<DATE(2020,3,1),"Pre-COVID","Post-COVID") -> Pre-COVID | AS14: =MONTH(DATEVALUE("1 "& C14)) -> 5
... A23: Rural | B23: 2013 | C23: august | D23: 8 | E23: 41487 | F23: 114.3 | G23: 115.4 | H23: 111.1 | I23: 110 | J23: 106.4 | K23: 110.8 | L23: 138.9 | M23: 107.4 | N23: 104.1 | O23: 106.9 | P23: 109.7 | Q23: 112.6 | R23: 114.9 | S23: 110.7 | T23: 111.3 | U23: 110.2 | V23: 111.1 | W23: 0 | X23: 109.9 | Y23: 108.7 | Z23: 107.5 | AA23: 107.8 | AB23: 106.8 | AC23: 108.7 | AD23: 105 | AE23: 107.5 | AF23: 112.1 | AG23: 1356.1 | AH23: 0 | AI23: 866.5 | AJ23: 106.4 | AK23: 110.7 | AL23: 332.6 | AM23: =VLOOKUP(E23,CRUIDdata!C:D,2,FALSE) -> 107 | AN23: Pre-COVID | AO23: =IF(AND(K23>150,L23>150),"no") -> FALSE | AQ23: =DATE(B23,MONTH(1&TRIM(C23)),1) -> 41487 | AR23: =IF(E23<DATE(2020,3,1),"Pre-COVID","Post-COVID") -> Pre-COVID | AS23: =MONTH(DATEVALUE("1 "& C23)) -> 8
A24: Urban | B24: 2013 | C24: august | D24: 8 | E24: 41487 | F24: 118.3 | G24: 120.4 | H24: 112.7 | I24: 108.9 | J24: 101.1 | K24: 108.7 | L24: 177 | M24: 104.7 | N24: 101 | O24: 108.5 | P24: 110.9 | Q24: 114.3 | R24: 119.6 | S24: 112.4 | T24: 110.6 | U24: 108.3 | V24: 110.2 | W24: 108.9 | X24: 109.3 | Y24: 108.7 | Z24: 107.6 | AA24: 108.1 | AB24: 106.5 | AC24: 110.8 | AD24: 106 | AE24: 108.3 | AF24: 112.7 | AG24: 1405 | AH24: 108.9 | AI24: 870.4 | AJ24: 101.1 | AK24: 112.4 | AL24: 329.1 | AM24: =VLOOKUP(E24,CRUIDdata!C:D,2,FALSE) -> 107 | AN24: Pre-COVID | AO24: =IF(AND(K24>150,L24>150),"no") -> FALSE | AP24: =COUNTIF(AO:AO,"no") -> 91 | AQ24: =DATE(B24,MONTH(1&TRIM(C24)),1) -> 41487 | AR24: =IF(E24<DATE(2020,3,1),"Pre-COVID","Post-COVID") -> Pre-COVID | AS24: =MONTH(DATEVALUE("1 "& C24)) -> 8
A25: Rural+Urban | B25: 2013 | C25: august | D25: 8 | E25: 41487 | F25: 115.6 | G25: 117.2 | H25: 111.7 | I25: 109.6 | J25: 104.5 | K25: 109.8 | L25: 151.8 | M25: 106.5 | N25: 103.1 | O25: 107.4 | P25: 110.2 | Q25: 113.4 | R25: 116.6 | S25: 111.2 | T25: 111 | U25: 109.4 | V25: 110.7 | W25: 108.9 | X25: 109.7 | Y25: 108.7 | Z25: 107.5 | AA25: 108 | AB25: 106.6 | AC25: 109.9 | AD25: 105.4 | AE25: 107.9 | AF25: 112.4 | AG25: 1372.9 | AH25: 108.9 | AI25: 868.6 | AJ25: 104.5 | AK25: 111.2 | AL25: 331.1 | AM25: =VLOOKUP(E25,CRUIDdata!C:D,2,FALSE) -> 107 | AN25: Pre-COVID | AO25: =IF(AND(K25>150,L25>150),"no") -> FALSE | AP25: =COUNTIF(AO:AO,"no") -> 91 | AQ25: =DATE(B25,MONTH(1&TRIM(C25)),1) -> 41487 | AR25: =IF(E25<DATE(2020,3,1),"Pre-COVID","Post-COVID") -> Pre-COVID | AS25: =MONTH(DATEVALUE("1 "& C25)) -> 8
A26: Rural | B26: 2013 | C26: september | D26: 9 | E26: 41518 | F26: 115.4 | G26: 115.7 | H26: 111.7 | I26: 111 | J26: 107.4 | K26: 110.9 | L26: 154 | M26: 108.1 | N26: 104.2 | O26: 107.9 | P26: 110.4 | Q26: 114 | R26: 117.8 | S26: 111.7 | T26: 112.7 | U26: 111.4 | V26: 112.5 | W26: 0 | X26: 111.1 | Y26: 109.6 | Z26: 108.3 | AA26: 109.3 | AB26: 107.7 | AC26: 109.8 | AD26: 106.7 | AE26: 108.7 | AF26: 114.2 | AG26: 1381.1 | AH26: 0 | AI26: 877.1 | AJ26: 107.4 | AK26: 111.7 | AL26: 336.6 | AM26: =VLOOKUP(E26,CRUIDdata!C:D,2,FALSE) -> 102 | AN26: Pre-COVID | AO26: =IF(AND(K26>150,L26>150),"no") -> FALSE | AP26: =COUNTIF(AO:AO,"no") -> 91 | AQ26: =DATE(B26,MONTH(1&TRIM(C26)),1) -> 41518 | AR26: =IF(E26<DATE(2020,3,1),"Pre-COVID","Post-COVID") -> Pre-COVID | AS26: =MONTH(DATEVALUE("1 "& C26)) -> 9
A27: Urban | B27: 2013 | C27: september | D27: 9 | E27: 41518 | F27: 118.6 | G27: 119.1 | H27: 113.2 | I27: 109.6 | J27: 101.7 | K27: 103.2 | L27: 174.3 | M27: 105.1 | N27: 100.8 | O27: 109.1 | P27: 111.1 | Q27: 115.4 | R27: 119.2 | S27: 112.9 | T27: 111.4 | U27: 109 | V27: 111.1 | W27: 109.7 | X27: 109.5 | Y27: 109.6 | Z27: 107.9 | AA27: 110.4 | AB27: 107.4 | AC27: 111.2 | AD27: 106.9 | AE27: 109.4 | AF27: 113.2 | AG27: 1398.7 | AH27: 109.7 | AI27: 877.6 | AJ27: 101.7 | AK27: 112.9 | AL27: 331.5 | AM27: =VLOOKUP(E27,CRUIDdata!C:D,2,FALSE) -> 102 | AN27: Pre-COVID | AO27: =IF(AND(K27>150,L27>150),"no") -> FALSE | AP27: =COUNTIF(AO:AO,"no") -> 91 | AQ27: =DATE(B27,MONTH(1&TRIM(C27)),1) -> 41518 | AR27: =IF(E27<DATE(2020,3,1),"Pre-COVID","Post-COVID") -> Pre-COVID | AS27: =MONTH(DATEVALUE("1 "& C27)) -> 9
A28: Rural+Urban | B28: 2013 | C28: september | D28: 9 | E28: 41518 | F28: 116.4 | G28: 116.9 | H28: 112.3 | I28: 110.5 | J28: 105.3 | K28: 107.3 | L28: 160.9 | M28: 107.1 | N28: 103.1 | O28: 108.3 | P28: 110.7 | Q28: 114.6 | R28: 118.3 | S28: 112 | T28: 112.2 | U28: 110.4 | V28: 111.9 | W28: 109.7 | X28: 110.5 | Y28: 109.6 | Z28: 108.1 | AA28: 109.9 | AB28: 107.5 | AC28: 110.6 | AD28: 106.8 | AE28: 109 | AF28: 113.7 | AG28: 1386.4 | AH28: 109.7 | AI28: 877.6 | AJ28: 105.3 | AK28: 112 | AL28: 334.5 | AM28: =VLOOKUP(E28,CRUIDdata!C:D,2,FALSE) -> 102 | AN28: Pre-COVID | AO28: =IF(AND(K28>150,L28>150),"no") -> FALSE | AP28: =COUNTIF(AO:AO,"no") -> 91 | AQ28: =DATE(B28,MONTH(1&TRIM(C28)),1) -> 41518 | AR28: =IF(E28<DATE(2020,3,1),"Pre-COVID","Post-COVID") -> Pre-COVID | AS28: =MONTH(DATEVALUE("1 "& C28)) -> 9
A29: Rural | B29: 2013 | C29: october | D29: 10 | E29: 41548 | F29: 116.3 | G29: 115.4 | H29: 112.6 | I29: 111.7 | J29: 107.7 | K29: 113.2 | L29: 164.9 | M29: 108.3 | N29: 103.9 | O29: 108.2 | P29: 111.1 | Q29: 114.9 | R29: 119.8 | S29: 112.2 | T29: 113.6 | U29: 112.3 | V29: 113.4 | W29: 0 | X29: 111.6 | Y29: 110.4 | Z29: 108.9 | AA29: 109.3 | AB29: 108.3 | AC29: 110.2 | AD29: 107.5 | AE29: 109.1 | AF29: 115.5 | AG29: 1400.3 | AH29: 0 | AI29: 881.9 | AJ29: 107.7 | AK29: 112.2 | AL29: 339.3 | AM29: =VLOOKUP(E29,CRUIDdata!C:D,2,FALSE) -> 97 | AN29: Pre-COVID | AO29: =IF(AND(K29>150,L29>150),"no") -> FALSE | AP29: =COUNTIF(AO:AO,"no") -> 91 | AQ29: =DATE(B29,MONTH(1&TRIM(C29)),1) -> 41548 | AR29: =IF(E29<DATE(2020,3,1),"Pre-COVID","Post-COVID") -> Pre-COVID | AS29: =MONTH(DATEVALUE("1 "& C29)) -> 10
A30: Urban | B30: 2013 | C30: october | D30: 10 | E30: 41548 | F30: 118.9 | G30: 118.1 | H30: 114.5 | I30: 110.4 | J30: 102.3 | K30: 106.2 | L30: 183.5 | M30: 105.3 | N30: 100.2 | O30: 109.6 | P30: 111.4 | Q30: 116 | R30: 120.8 | S30: 113.5 | T30: 112.5 | U30: 109.7 | V30: 112 | W30: 110.5 | X30: 109.7 | Y30: 110.2 | Z30: 108.2 | AA30: 109.7 | AB30: 108 | AC30: 111.3 | AD30: 107.3 | AE30: 109.4 | AF30: 114 | AG30: 1414.9 | AH30: 110.5 | AI30: 879.6 | AJ30: 102.3 | AK30: 113.5 | AL30: 334.2 | AM30: =VLOOKUP(E30,CRUIDdata!C:D,2,FALSE) -> 97 | AN30: Pre-COVID | AO30: =IF(AND(K30>150,L30>150),"no") -> FALSE | AP30: =COUNTIF(AO:AO,"no") -> 91 | AQ30: =DATE(B30,MONTH(1&TRIM(C30)),1) -> 41548 | AR30: =IF(E30<DATE(2020,3,1),"Pre-COVID","Post-COVID") -> Pre-COVID | AS30: =MONTH(DATEVALUE("1 "& C30)) -> 10
A31: Rural+Urban | B31: 2013 | C31: october | D31: 10 | E31: 41548 | F31: 117.1 | G31: 116.3 | H31: 113.3 | I31: 111.2 | J31: 105.7 | K31: 109.9 | L31: 171.2 | M31: 107.3 | N31: 102.7 | O31: 108.7 | P31: 111.2 | Q31: 115.4 | R31: 120.2 | S31: 112.5 | T31: 113.2 | U31: 111.2 | V31: 112.8 | W31: 110.5 | X31: 110.9 | Y31: 110.3 | Z31: 108.6 | AA31: 109.5 | AB31: 108.1 | AC31: 110.8 | AD31: 107.4 | AE31: 109.2 | AF31: 114.8 | AG31: 1404.5 | AH31: 110.5 | AI31: 881 | AJ31: 105.7 | AK31: 112.5 | AL31: 337.2 | AM31: =VLOOKUP(E31,CRUIDdata!C:D,2,FALSE) -> 97 | AN31: Pre-COVID | AO31: =IF(AND(K31>150,L31>150),"no") -> FALSE | AP31: =COUNTIF(AO:AO,"no") -> 91 | AQ31: =DATE(B31,MONTH(1&TRIM(C31)),1) -> 41548 | AR31: =IF(E31<DATE(2020,3,1),"Pre-COVID","Post-COVID") -> Pre-COVID | AS31: =MONTH(DATEVALUE("1 "& C31)) -> 10
A32: Rural | B32: 2013 | C32: november | D32: 11 | E32: 41579 | F32: 117.3 | G32: 114.9 | H32: 116.2 | I32: 112.8 | J32: 108.9 | K32: 116.6 | L32: 178.1 | M32: 109.1 | N32: 103.6 | O32: 109 | P32: 111.8 | Q32: 116 | R32: 122.5 | S32: 112.8 | T32: 114.6 | U32: 113.1 | V32: 114.4 | W32: 0 | X32: 112.6 | Y32: 111.3 | Z32: 109.7 | AA32: 109.6 | AB32: 108.7 | AC32: 111 | AD32: 108.2 | AE32: 109.8 | AF32: 117.4 | AG32: 1427.9 | AH32: 0 | AI32: 888.6 | AJ32: 108.9 | AK32: 112.8 | AL32: 342.1 | AM32: =VLOOKUP(E32,CRUIDdata!C:D,2,FALSE) -> 94 | AN32: Pre-COVID | AO32: =IF(AND(K32>150,L32>150),"no") -> FALSE | AP32: =COUNTIF(AO:AO,"no") -> 91 | AQ32: =DATE(B32,MONTH(1&TRIM(C32)),1) -> 41579 | AR32: =IF(E32<DATE(2020,3,1),"Pre-COVID","Post-COVID") -> Pre-COVID | AS32: =MONTH(DATEVALUE("1 "& C32)) -> 11
A33: Urban | B33: 2013 | C33: november | D33: 11 | E33: 41579 | F33: 119.8 | G33: 116.3 | H33: 122.6 | I33: 112 | J33: 103.2 | K33: 110 | L33: 192.8 | M33: 106.3 | N33: 99.5 | O33: 110.3 | P33: 111.8 | Q33: 117.1 | R33: 122.9 | S33: 114.1 | T33: 113.5 | U33: 110.3 | V33: 113 | W33: 111.1 | X33: 110 | Y33: 110.9 | Z33: 108.6 | AA33: 109.5 | AB33: 108.5 | AC33: 111.3 | AD33: 107.9 | AE33: 109.6 | AF33: 115 | AG33: 1441.4 | AH33: 111.1 | AI33: 882.7 | AJ33: 103.2 | AK33: 114.1 | AL33: 336.8 | AM33: =VLOOKUP(E33,CRUIDdata!C:D,2,FALSE) -> 94 | AN33: Pre-COVID | AO33: =IF(AND(K33>150,L33>150),"no") -> FALSE | AP33: =COUNTIF(AO:AO,"no") -> 91 | AQ33: =DATE(B33,MONTH(1&TRIM(C33)),1) -> 41579 | AR33: =IF(E33<DATE(2020,3,1),"Pre-COVID","Post-COVID") -> Pre-COVID | AS33: =MONTH(DATEVALUE("1 "& C33)) -> 11
A34: Rural+Urban | B34: 2013 | C34: november | D34: 11 | E34: 41579 | F34: 118.1 | G34: 115.4 | H34: 118.7 | I34: 112.5 | J34: 106.8 | K34: 113.5 | L34: 183.1 | M34: 108.2 | N34: 102.2 | O34: 109.4 | P34: 111.8 | Q34: 116.5 | R34: 122.6 | S34: 113.1 | T34: 114.2 | U34: 111.9 | V34: 113.8 | W34: 111.1 | X34: 111.6 | Y34: 111.1 | Z34: 109.3 | AA34: 109.5 | AB34: 108.6 | AC34: 111.2 | AD34: 108.1 | AE34: 109.7 | AF34: 116.3 | AG34: 1432 | AH34: 111.1 | AI34: 886.1 | AJ34: 106.8 | AK34: 113.1 | AL34: 339.9 | AM34: =VLOOKUP(E34,CRUIDdata!C:D,2,FALSE) -> 94 | AN34: Pre-COVID | AO34: =IF(AND(K34>150,L34>150),"no") -> FALSE | AP34: =COUNTIF(AO:AO,"no") -> 91 | AQ34: =DATE(B34,MONTH(1&TRIM(C34)),1) -> 41579 | AR34: =IF(E34<DATE(2020,3,1),"Pre-COVID","Post-COVID") -> Pre-COVID | AS34: =MONTH(DATEVALUE("1 "& C34)) -> 11
A35: Rural | B35: 2013 | C35: december | D35: 12 | E35: 41609 | F35: 118.4 | G35: 115.9 | H35: 120.4 | I35: 113.8 | J35: 109.5 | K35: 115.5 | L35: 145.7 | M35: 109.5 | N35: 102.9 | O35: 109.8 | P35: 112.1 | Q35: 116.8 | R35: 118.7 | S35: 113.6 | T35: 115.8 | U35: 114 | V35: 115.5 | W35: 0 | X35: 112.8 | Y35: 112.1 | Z35: 110.1 | AA35: 109.9 | AB35: 109.2 | AC35: 111.6 | AD35: 108.1 | AE35: 110.1 | AF35: 115.5 | AG35: 1399.5 | AH35: 0 | AI35: 889.3 | AJ35: 109.5 | AK35: 113.6 | AL35: 345.3 | AM35: =VLOOKUP(E35,CRUIDdata!C:D,2,FALSE) -> 98 | AN35: Pre-COVID | AO35: =IF(AND(K35>150,L35>150),"no") -> FALSE | AP35: =COUNTIF(AO:AO,"no") -> 91 | AQ35: =DATE(B35,MONTH(1&TRIM(C35)),1) -> 41609 | AR35: =IF(E35<DATE(2020,3,1),"Pre-COVID","Post-COVID") -> Pre-COVID | AS35: =MONTH(DATEVALUE("1 "& C35)) -> 12
... A262: Rural+Urban | B262: 2020 | C262: april | D262: 4 | E262: 43922 | F262: 148.7 | G262: 0 | H262: 148.8 | I262: 155.6 | J262: 135.1 | K262: 149.9 | L262: 168.6 | M262: 150.4 | N262: 120.3 | O262: 157.1 | P262: 136.8 | Q262: 0 | R262: 151.4 | S262: 0 | T262: 0 | U262: 0 | V262: 0 | W262: 155.6 | X262: 144.1 | Y262: 0 | Z262: 150.7 | AA262: 0 | AB262: 0 | AC262: 0 | AD262: 0 | AE262: 0 | AF262: 0 | AG262: 1487.6 | AH262: 155.6 | AI262: 144.1 | AJ262: 135.1 | AK262: 0 | AL262: 0 | AM262: =VLOOKUP(E262,CRUIDdata!C:D,2,FALSE) -> 17 | AN262: Post-COVID | AO262: =IF(AND(K262>150,L262>150),"no") -> FALSE | AP262: =COUNTIF(AO:AO,"no") -> 91 | AQ262: =DATE(B262,MONTH(1&TRIM(C262)),1) -> 43922 | AR262: =IF(E262<DATE(2020,3,1),"Pre-COVID","Post-COVID") -> Post-COVID | AS262: =MONTH(DATEVALUE("1 "& C262)) -> 4
A263: Rural | B263: 2020 | C263: may | D263: 5 | E263: 43952 | F263: 0 | G263: 0 | H263: 0 | I263: 0 | J263: 0 | K263: 0 | L263: 0 | N263: 0 | O263: 0 | P263: 0 | Q263: 0 | R263: 0 | S263: 0 | T263: 0 | U263: 0 | V263: 0 | W263: 0 | X263: 0 | Y263: 0 | Z263: 0 | AA263: 0 | AB263: 0 | AC263: 0 | AD263: 0 | AE263: 0 | AF263: 0 | AH263: 0 | AI263: 0 | AJ263: 0 | AK263: 0 | AL263: 0 | AM263: =VLOOKUP(E263,CRUIDdata!C:D,2,FALSE) -> 25 | AN263: Post-COVID | AO263: =IF(AND(K263>150,L263>150),"no") -> FALSE | AP263: =COUNTIF(AO:AO,"no") -> 91 | AQ263: =DATE(B263,MONTH(1&TRIM(C263)),1) -> 43952 | AR263: =IF(E263<DATE(2020,3,1),"Pre-COVID","Post-COVID") -> Post-COVID | AS263: =MONTH(DATEVALUE("1 "& C263)) -> 5
A264: Urban | B264: 2020 | C264: may | D264: 5 | E264: 43952 | F264: 0 | G264: 0 | H264: 0 | I264: 0 | J264: 0 | K264: 0 | L264: 0 | N264: 0 | O264: 0 | P264: 0 | Q264: 0 | R264: 0 | S264: 0 | T264: 0 | U264: 0 | V264: 0 | W264: 0 | X264: 0 | Y264: 0 | Z264: 0 | AA264: 0 | AB264: 0 | AC264: 0 | AD264: 0 | AE264: 0 | AF264: 0 | AH264: 0 | AI264: 0 | AJ264: 0 | AK264: 0 | AL264: 0 | AM264: =VLOOKUP(E264,CRUIDdata!C:D,2,FALSE) -> 25 | AN264: Post-COVID | AO264: =IF(AND(K264>150,L264>150),"no") -> FALSE | AP264: =COUNTIF(AO:AO,"no") -> 91 | AQ264: =DATE(B264,MONTH(1&TRIM(C264)),1) -> 43952 | AR264: =IF(E264<DATE(2020,3,1),"Pre-COVID","Post-COVID") -> Post-COVID | AS264: =MONTH(DATEVALUE("1 "& C264)) -> 5
A265: Rural+Urban | B265: 2020 | C265: may | D265: 5 | E265: 43952 | F265: 0 | G265: 0 | H265: 0 | I265: 0 | J265: 0 | K265: 0 | L265: 0 | N265: 0 | O265: 0 | P265: 0 | Q265: 0 | R265: 0 | S265: 0 | T265: 0 | U265: 0 | V265: 0 | W265: 0 | X265: 0 | Y265: 0 | Z265: 0 | AA265: 0 | AB265: 0 | AC265: 0 | AD265: 0 | AE265: 0 | AF265: 0 | AH265: 0 | AI265: 0 | AJ265: 0 | AK265: 0 | AL265: 0 | AM265: =VLOOKUP(E265,CRUIDdata!C:D,2,FALSE) -> 25 | AN265: Post-COVID | AO265: =IF(AND(K265>150,L265>150),"no") -> FALSE | AP265: =COUNTIF(AO:AO,"no") -> 91 | AQ265: =DATE(B265,MONTH(1&TRIM(C265)),1) -> 43952 | AR265: =IF(E265<DATE(2020,3,1),"Pre-COVID","Post-COVID") -> Post-COVID | AS265: =MONTH(DATEVALUE("1 "& C265)) -> 5
A266: Rural | B266: 2020 | C266: june | D266: 6 | E266: 43983 | F266: 148.2 | G266: 190.3 | H266: 149.4 | I266: 153.3 | J266: 138.2 | K266: 143.2 | L266: 148.9 | M266: 150.3 | N266: 113.2 | O266: 159.8 | P266: 142.1 | Q266: 161.8 | R266: 152.3 | S266: 182.4 | T266: 154.7 | U266: 150 | V266: 154.1 | W266: 0 | X266: 144.9 | Y266: 151.7 | Z266: 158.2 | AA266: 141.4 | AB266: 153.2 | AC266: 161.8 | AD266: 151.2 | AE266: 151.7 | AF266: 152.7 | AG266: 1812.8 | AH266: 0 | AI266: 1208.6 | AJ266: 138.2 | AK266: 182.4 | AL266: 458.8 | AM266: =VLOOKUP(E266,CRUIDdata!C:D,2,FALSE) -> 38 | AN266: Post-COVID | AO266: =IF(AND(K266>150,L266>150),"no") -> FALSE | AP266: =COUNTIF(AO:AO,"no") -> 91 | AQ266: =DATE(B266,MONTH(1&TRIM(C266)),1) -> 43983 | AR266: =IF(E266<DATE(2020,3,1),"Pre-COVID","Post-COVID") -> Post-COVID | AS266: =MONTH(DATEVALUE("1 "& C266)) -> 6
A267: Urban | B267: 2020 | C267: june | D267: 6 | E267: 43983 | F267: 152.7 | G267: 197 | H267: 154.6 | I267: 153.4 | J267: 132.9 | K267: 151.8 | L267: 171.2 | M267: 152 | N267: 116.3 | O267: 158.8 | P267: 135.6 | Q267: 161.7 | R267: 157 | S267: 186.7 | T267: 149.1 | U267: 136.6 | V267: 147.2 | W267: 154.7 | X267: 137.1 | Y267: 140.4 | Z267: 148.1 | AA267: 129.3 | AB267: 144.5 | AC267: 152.5 | AD267: 152.2 | AE267: 142 | AF267: 150.8 | AG267: 1862.1 | AH267: 154.7 | AI267: 1148.8 | AJ267: 132.9 | AK267: 186.7 | AL267: 432.9 | AM267: =VLOOKUP(E267,CRUIDdata!C:D,2,FALSE) -> 38 | AN267: Post-COVID | AO267: =IF(AND(K267>150,L267>150),"no") -> no | AP267: =COUNTIF(AO:AO,"no") -> 91 | AQ267: =DATE(B267,MONTH(1&TRIM(C267)),1) -> 43983 | AR267: =IF(E267<DATE(2020,3,1),"Pre-COVID","Post-COVID") -> Post-COVID | AS267: =MONTH(DATEVALUE("1 "& C267)) -> 6
A268: Rural+Urban | B268: 2020 | C268: june | D268: 6 | E268: 43983 | F268: 149.6 | G268: 192.7 | H268: 151.4 | I268: 153.3 | J268: 136.3 | K268: 147.2 | L268: 156.5 | M268: 150.9 | N268: 114.2 | O268: 159.5 | P268: 139.4 | Q268: 161.8 | R268: 154 | S268: 183.5 | T268: 152.5 | U268: 144.4 | V268: 151.4 | W268: 154.7 | X268: 141.9 | Y268: 146.4 | Z268: 154.4 | AA268: 135 | AB268: 148.3 | AC268: 156.4 | AD268: 151.6 | AE268: 147 | AF268: 151.8 | AG268: 1830.5 | AH268: 154.7 | AI268: 1178.4 | AJ268: 136.3 | AK268: 183.5 | AL268: 448.3 | AM268: =VLOOKUP(E268,CRUIDdata!C:D,2,FALSE) -> 38 | AN268: Post-COVID | AO268: =IF(AND(K268>150,L268>150),"no") -> FALSE | AP268: =COUNTIF(AO:AO,"no") -> 91 | AQ268: =DATE(B268,MONTH(1&TRIM(C268)),1) -> 43983 | AR268: =IF(E268<DATE(2020,3,1),"Pre-COVID","Post-COVID") -> Post-COVID | AS268: =MONTH(DATEVALUE("1 "& C268)) -> 6
A269: Rural | B269: 2020 | C269: july | D269: 7 | E269: 44013 | F269: 148.2 | G269: 190.3 | H269: 149.4 | I269: 153.3 | J269: 138.2 | K269: 143.2 | L269: 148.9 | M269: 150.3 | N269: 113.2 | O269: 159.8 | P269: 142.1 | Q269: 161.8 | R269: 152.3 | S269: 182.4 | T269: 154.7 | U269: 150 | V269: 154.1 | W269: 0 | X269: 144.9 | Y269: 151.7 | Z269: 158.2 | AA269: 141.4 | AB269: 153.2 | AC269: 161.8 | AD269: 151.2 | AE269: 151.7 | AF269: 152.7 | AG269: 1812.8 | AH269: 0 | AI269: 1208.6 | AJ269: 138.2 | AK269: 182.4 | AL269: 458.8 | AM269: =VLOOKUP(E269,CRUIDdata!C:D,2,FALSE) -> 42 | AN269: Post-COVID | AO269: =IF(AND(K269>150,L269>150),"no") -> FALSE | AP269: =COUNTIF(AO:AO,"no") -> 91 | AQ269: =DATE(B269,MONTH(1&TRIM(C269)),1) -> 44013 | AR269: =IF(E269<DATE(2020,3,1),"Pre-COVID","Post-COVID") -> Post-COVID | AS269: =MONTH(DATEVALUE("1 "& C269)) -> 7
A270: Urban | B270: 2020 | C270: july | D270: 7 | E270: 44013 | F270: 152.7 | G270: 197 | H270: 154.6 | I270: 153.4 | J270: 132.9 | K270: 151.8 | L270: 171.2 | M270: 152 | N270: 116.3 | O270: 158.8 | P270: 135.6 | Q270: 161.7 | R270: 157 | S270: 186.7 | T270: 149.1 | U270: 136.6 | V270: 147.2 | W270: 154.7 | X270: 137.1 | Y270: 140.4 | Z270: 148.1 | AA270: 129.3 | AB270: 144.5 | AC270: 152.5 | AD270: 152.2 | AE270: 142 | AF270: 150.8 | AG270: 1862.1 | AH270: 154.7 | AI270: 1148.8 | AJ270: 132.9 | AK270: 186.7 | AL270: 432.9 | AM270: =VLOOKUP(E270,CRUIDdata!C:D,2,FALSE) -> 42 | AN270: Post-COVID | AO270: =IF(AND(K270>150,L270>150),"no") -> no | AP270: =COUNTIF(AO:AO,"no") -> 91 | AQ270: =DATE(B270,MONTH(1&TRIM(C270)),1) -> 44013 | AR270: =IF(E270<DATE(2020,3,1),"Pre-COVID","Post-COVID") -> Post-COVID | AS270: =MONTH(DATEVALUE("1 "& C270)) -> 7
A271: Rural+Urban | B271: 2020 | C271: july | D271: 7 | E271: 44013 | F271: 149.6 | G271: 192.7 | H271: 151.4 | I271: 153.3 | J271: 136.3 | K271: 147.2 | L271: 156.5 | M271: 150.9 | N271: 114.2 | O271: 159.5 | P271: 139.4 | Q271: 161.8 | R271: 154 | S271: 183.5 | T271: 152.5 | U271: 144.4 | V271: 151.4 | W271: 154.7 | X271: 141.9 | Y271: 146.4 | Z271: 154.4 | AA271: 135 | AB271: 148.3 | AC271: 156.4 | AD271: 151.6 | AE271: 147 | AF271: 151.8 | AG271: 1830.5 | AH271: 154.7 | AI271: 1178.4 | AJ271: 136.3 | AK271: 183.5 | AL271: 448.3 | AM271: =VLOOKUP(E271,CRUIDdata!C:D,2,FALSE) -> 42 | AN271: Post-COVID | AO271: =IF(AND(K271>150,L271>150),"no") -> FALSE | AP271: =COUNTIF(AO:AO,"no") -> 91 | AQ271: =DATE(B271,MONTH(1&TRIM(C271)),1) -> 44013 | AR271: =IF(E271<DATE(2020,3,1),"Pre-COVID","Post-COVID") -> Post-COVID | AS271: =MONTH(DATEVALUE("1 "& C271)) -> 7
A272: Rural | B272: 2020 | C272: august | D272: 8 | E272: 44044 | F272: 147.6 | G272: 187.2 | H272: 148.4 | I272: 153.3 | J272: 139.8 | K272: 146.9 | L272: 171 | M272: 149.9 | N272: 114.2 | O272: 160 | P272: 143.5 | Q272: 161.5 | R272: 155.3 | S272: 180.9 | T272: 155.1 | U272: 149.3 | V272: 154.3 | W272: 0 | X272: 145.8 | Y272: 151.9 | Z272: 158.8 | AA272: 143.6 | AB272: 152.2 | AC272: 162.7 | AD272: 153.6 | AE272: 153 | AF272: 154.7 | AG272: 1838.8 | AH272: 0 | AI272: 1217.5 | AJ272: 139.8 | AK272: 180.9 | AL272: 458.7 | AM272: =VLOOKUP(E272,CRUIDdata!C:D,2,FALSE) -> 45 | AN272: Post-COVID | AO272: =IF(AND(K272>150,L272>150),"no") -> FALSE | AP272: =COUNTIF(AO:AO,"no") -> 91 | AQ272: =DATE(B272,MONTH(1&TRIM(C272)),1) -> 44044 | AR272: =IF(E272<DATE(2020,3,1),"Pre-COVID","Post-COVID") -> Post-COVID | AS272: =MONTH(DATEVALUE("1 "& C272)) -> 8
A273: Urban | B273: 2020 | C273: august | D273: 8 | E273: 44044 | F273: 151.6 | G273: 197.8 | H273: 154.5 | I273: 153.4 | J273: 133.4 | K273: 154.5 | L273: 191.9 | M273: 151.3 | N273: 116.8 | O273: 160 | P273: 136.5 | Q273: 163.3 | R273: 159.9 | S273: 187.2 | T273: 150 | U273: 135.2 | V273: 147.8 | W273: 155.5 | X273: 138.3 | Y273: 144.5 | Z273: 148.7 | AA273: 133.9 | AB273: 141.2 | AC273: 155.5 | AD273: 155.2 | AE273: 144.8 | AF273: 152.9 | AG273: 1891.5 | AH273: 155.5 | AI273: 1166.3 | AJ273: 133.4 | AK273: 187.2 | AL273: 433 | AM273: =VLOOKUP(E273,CRUIDdata!C:D,2,FALSE) -> 45 | AN273: Post-COVID | AO273: =IF(AND(K273>150,L273>150),"no") -> no | AP273: =COUNTIF(AO:AO,"no") -> 91 | AQ273: =DATE(B273,MONTH(1&TRIM(C273)),1) -> 44044 | AR273: =IF(E273<DATE(2020,3,1),"Pre-COVID","Post-COVID") -> Post-COVID | AS273: =MONTH(DATEVALUE("1 "& C273)) -> 8
A274: Rural+Urban | B274: 2020 | C274: august | D274: 8 | E274: 44044 | F274: 148.9 | G274: 190.9 | H274: 150.8 | I274: 153.3 | J274: 137.4 | K274: 150.4 | L274: 178.1 | M274: 150.4 | N274: 115.1 | O274: 160 | P274: 140.6 | Q274: 162.3 | R274: 157 | S274: 182.6 | T274: 153.1 | U274: 143.4 | V274: 151.7 | W274: 155.5 | X274: 143 | Y274: 148.4 | Z274: 155 | AA274: 138.5 | AB274: 146 | AC274: 158.5 | AD274: 154.3 | AE274: 149 | AF274: 153.9 | AG274: 1857.8 | AH274: 155.5 | AI274: 1191.6 | AJ274: 137.4 | AK274: 182.6 | AL274: 448.2 | AM274: =VLOOKUP(E274,CRUIDdata!C:D,2,FALSE) -> 45 | AN274: Post-COVID | AO274: =IF(AND(K274>150,L274>150),"no") -> no | AP274: =COUNTIF(AO:AO,"no") -> 91 | AQ274: =DATE(B274,MONTH(1&TRIM(C274)),1) -> 44044 | AR274: =IF(E274<DATE(2020,3,1),"Pre-COVID","Post-COVID") -> Post-COVID | AS274: =MONTH(DATEVALUE("1 "& C274)) -> 8
...

Sheet 1Bucket Details
A1: Based on the latest month’s CPI data, the Food category has the highest contribution to the CPI basket, accounting for nearly half (≈47%) of the overall weight. This indicates that food price fluctuations have the strongest influence on inflation trends. The Miscellaneous category is the second-largest contributor (≈30%), followed by Clothing & Footwear (≈12%). Housing, Oils & Fats, and Paan & Tobacco contribute smaller shares (<5% each). Collectively, Food and Miscellaneous account for almost 80% of the total CPI basket, highlighting their dominant role in driving consumer price inflation. Formula used for sum of buclerts SUMIF(FinalCPIData!AG2:AG500, "<>#N/A") %of Each bucket (B5/$B$12)*100
A4: Bucket Name | B4: Sum of Buckets | C4: %of Each bucket
A5: FoodBucket | B5: =SUMIF(cpiassignment!AG2:AG500, "<>#N/A") -> 623887.5 | C5: =(B5/$B$12)*100 -> 47.47189 | G5: Bucket Name | H5: %of Each bucket
A6: MiscellaneousBucket | B6: =SUMIF(cpiassignment!AI2:AI500, "<>#N/A") -> 396619.4 | C6: =(B6/$B$12)*100 -> 30.178955 | G6: FoodBucket | H6: =(B6/$B$12)*100 -> 30.178955
A7: Clothing and footwearbucket | B7: =SUMIF(cpiassignment!AL2:AL500, "<>#N/A") -> 153835.4 | C7: =(B7/$B$12)*100 -> 11.705407 | G7: MiscellaneousBucket | H7: =(B7/$B$12)*100 -> 11.705407
A8: Pantobaccobuckets | B8: =SUMIF(cpiassignment!AK2:AK500, "<>#N/A") -> 56871.2 | C8: =(B8/$B$12)*100 -> 4.3273561 | G8: Clothing and footwearbucket | H8: =(B8/$B$12)*100 -> 4.3273561
A9: Oils and fatsBuckets | B9: =SUMIF(cpiassignment!AJ2:AJ500, "<>#N/A") -> 48754.6 | C9: =(B9/$B$12)*100 -> 3.7097602 | G9: Pantobaccobuckets | H9: =(B9/$B$12)*100 -> 3.7097602
A10: Housingbucket | B10: =SUMIF(cpiassignment!AH2:AH500, "<>#N/A") -> 34257 | C10: =(B10/$B$12)*100 -> 2.6066311 | D10: %of Eachbucket | E10: =VLOOKUP("Housingbucket",A5:C10,3,FALSE) -> 2.6066311 | G10: Oils and fatsBuckets | H10: =(B10/$B$12)*100 -> 2.6066311
G11: Housingbucket | H11: =(B11/$B$12)*100 -> 0
A12: Sum of All Buckets | B12: =SUM(B5:B10) -> 1314225.1
G14: Bucket Names | H14: % contribution of Each bucket
G15: Housingbucket | H15: 2.6066311
G16: Oils and fatsBuckets | H16: 3.7097602
G17: Pantobaccobuckets | H17: 4.3273561
G18: Clothing and footwearbucket | H18: 11.705407
G19: MiscellaneousBucket | H19: 30.178955
G20: FoodBucket | H20: 47.47189

Sheet CRUIDdata
A1: Year | B1: Month | C1: Date | D1: Crude
A2: 2013 | B2: January | C2: =DATE(A2,MONTH(1&TRIM(B2)),1) -> 41275 | D2: 94
A3: 2013 | B3: February | C3: =DATE(A3,MONTH(1&TRIM(B3)),1) -> 41306 | D3: 95
A4: 2013 | B4: March | C4: =DATE(A4,MONTH(1&TRIM(B4)),1) -> 41334 | D4: 92
A5: 2013 | B5: April | C5: =DATE(A5,MONTH(1&TRIM(B5)),1) -> 41365 | D5: 91
A6: 2013 | B6: May | C6: =DATE(A6,MONTH(1&TRIM(B6)),1) -> 41395 | D6: 93
A7: 2013 | B7: June | C7: =DATE(A7,MONTH(1&TRIM(B7)),1) -> 41426 | D7: 95
A8: 2013 | B8: July | C8: =DATE(A8,MONTH(1&TRIM(B8)),1) -> 41456 | D8: 104
A9: 2013 | B9: August | C9: =DATE(A9,MONTH(1&TRIM(B9)),1) -> 41487 | D9: 107
A10: 2013 | B10: September | C10: =DATE(A10,MONTH(1&TRIM(B10)),1) -> 41518 | D10: 102
A11: 2013 | B11: October | C11: =DATE(A11,MONTH(1&TRIM(B11)),1) -> 41548 | D11: 97
A12: 2013 | B12: November | C12: =DATE(A12,MONTH(1&TRIM(B12)),1) -> 41579 | D12: 94
A13: 2013 | B13: December | C13: =DATE(A13,MONTH(1&TRIM(B13)),1) -> 41609 | D13: 98
... A133: 2023 | B133: December | C133: =DATE(A133,MONTH(1&TRIM(B133)),1) -> 45261 | D133: 75

Sheet 2.YOY FOR GENERAL INDEX
A1: 2. A trend of Y-o-Y increase in CPI (rural + urban) inflation starting 2017 for the entire basket of products combined. • Create a graph depicting the growth rate Y-o-Y and identify the year with highest inflation rate • Highlight the reason why the year has the highest inflation (based on research).
A7: Year | B7: YoY inflation %
A8: 2017
A9: 2018 | B9: 0.039609321
A10: 2019 | B10: -0.047254662
A11: 2020 | B11: -0.032862369
A12: 2021 | B12: 0.26328833
A13: 2022 | B13: 0.066029943
A14: 2023 | B14: -0.57001953
A18: Graph: Line chart of YoY CPI % (2017–2023). Annotation: Highlight 2021 (highest bar/point) in a different color. Text Insight: “Between 2017 and 2023, the highest YoY CPI inflation occurred in 2021 (≈26%). This was mainly driven by surging global edible oil prices, supply chain bottlenecks from the COVID-19 pandemic, and higher food prices. In comparison, inflation was relatively moderate in earlier years.”

Sheet  3.1.1Months Ending May 2023
A1: . With India’s retail inflation reaching a 3-month high of 5.55% in November 2023, largely due to a sharp rise in food prices. Analyze the following for 12 months ending May’23: • Investigate trends in the prices of broader food bucket category and evaluate month-on-month changes. Highlight month with highest and lowest food inflation • Identify the absolute changes in inflation over the same 12 months period and identify the biggest individual category contributor (only within broader food category) towards inflation ________________________________________
A6: Month | B6: Mom% Fruits | C6: Mom%Vegetables | D6: Mom%Food and beverages
A7: 44713
A8: 44743 | B8: 0.02688383 | C8: -0.0033862057 | D8: 0.00056969237
A9: 44774 | B9: -0.0078348939 | C9: 0.024499285 | D9: 0.0070222054
A10: 44805 | B10: -0.042180277 | C10: 0.028975388 | D10: 0.0084809649
A11: 44835 | B11: -0.011260808 | C11: 0.040033927 | D11: 0.0097178098
A12: 44866 | B12: -0.018913972 | C12: -0.086282825 | D12: -0.0075883768
A13: 44896 | B13: -0.016998342 | C13: -0.12745448 | D13: -0.013614323
A14: 44927 | B14: 0.0018979334 | C14: -0.034165303 | D14: 0.0043486481
A15: 44958 | B15: 0.070932435 | C15: -0.0057191273 | D15: 0.0024472892
A16: 44986 | B16: 0 | C16: 0.00042607584 | D16: 0.00018779343
A17: 45017 | B17: 0.04009434 | C17: 0.018100511 | D17: 0.0054449869
A18: 45047 | B18: -0.023053666 | C18: 0.03472077 | D18: 0.0065359477 | E18: =MIN(C8:C18) -> -0.12745448
A20: MoM % change in Food & Beverages Index shows the sharpest rise in Feb’23 (driven by Fruits at +7.1%) and the steepest fall in Dec’22 (due to Vegetables at -12.8%). Vegetables and Fruits were the most volatile categories driving overall food inflation during the 12-month period Contribution of Categories (Absolute Change over 12 months) Add Pivot where: Rows = Food categories ( Fruits, Vegetables, etc.) Values = Index of all Show Values As → Difference From → Base field: Month, Base item: First month (Jun’22) This gives you absolute change between Jun’22 and May’23 for each food category. Insert a bar chart → categories on Y-axis, absolute change on X-axis. Biggest bar = biggest contributor to food inflation.

Sheet 3.1.2 Same for Food Bucket 
A3: Date | B3: MOM - FoodBucket
A4: 44713
A5: 44743 | B5: 0.0044354123
A6: 44774 | B6: 0.0029064166
A7: 44805 | B7: 0.0075732104
A8: 44835 | B8: 0.0087875417
A9: 44866 | B9: -0.0019375266
A10: 44896 | B10: -0.0065025253
A11: 44927 | B11: 0.005321853
A12: 44958 | B12: -0.0024019089
A13: 44986 | B13: 9.5040471e-05
A14: 45017 | B14: 0.007238228
A15: 45047 | B15: 0.010315439
D32: MoM % changes in Food & Beverages (Jun’22–May’23) show high volatility — peaking in May’23 (+1.03%) and bottoming in Dec’22 (-0.65%), reflecting seasonal swings in food prices.

Sheet 4.Covid Trend
A1: Investigate how the onset and progression of the COVID-19 pandemic affected inflation rates in India. Analyze the impact of key pandemic milestone (first lockdown) on the CPI inflation %, specifically focus on categories like healthcare, food, and essential services. Hint: You can consider Mar’20 as the onset of covid, and can compare the inflation trend before and after Mar’20 to see if there is a change in inflation % before and after covid. if [Date] < #date(2020, 3, 1) then "Pre-COVID" else "Post-COVID"
B7: Year
A8: Buckets | B8: Post-COVID | C8: Pre-COVID
A9: Average of FoodBucket | B9: 1976.8254 | C9: 1562.8604
A10: Average of Housingbucket | B10: 106.47009 | C10: 85.490196
A11: Average of MiscellaneousBucket | B11: 1230.2479 | C11: 990.90353
A12: Average of Oils and fatsBuckets | B12: 167.31538 | C12: 114.42627
A13: Average of Pantobaccobuckets | B13: 182.44103 | C13: 139.31608
A14: Average of Clothing and footwearbucket | B14: 467.89573 | C14: 388.59451
A17: COVID-19 Impact on CPI Inflation in India Considering March 2020 as the onset of COVID-19 (first lockdown), a comparison of Pre- and Post-COVID averages across CPI buckets reveals a broad-based rise in inflation: Food Bucket rose from 1562.86 → 1976.83, marking the sharpest increase and confirming food as the primary inflation driver. Miscellaneous Bucket (which includes essential services) increased from 990.90 → 1230.25, showing strong service-related inflation post-COVID. Housing rose moderately (85.49 → 106.47), reflecting increased household costs. Oils & Fats (114.43 → 167.32) and Pan/Tobacco (139.32 → 182.44) also saw significant upward pressure. Clothing & Footwear rose from 388.59 → 467.90, adding to household expenditure burdens. Created Calculated colum in power query to get this data if [Date] < #date(2020, 3, 1) then "Pre-COVID" else "Post-COVID" Post-COVID inflation accelerated across all categories, but Food and Miscellaneous (services & essentials) were the largest contributors, highlighting how supply chain disruptions, higher healthcare demand, and food price shocks shaped India’s inflation trajectory during the pandemic.

Sheet 5.oiland Gas
A1: Investigate how major global economic events (like imported crude oil price fluctuations) have influenced India's inflation. This can include an analysis of imported goods and their price trends. • For the purpose of this analysis, focus only on the imported oil price fluctuations for years 2021 to 2023 (Month-on-month) • Identify trends in oil price change with change in inflation prices of all the categories and identify category whose inflation prices strongly changes with fluctuations in imported oil price (Hint: you can use =correl function) Formula CORREL(B8:B36, C8:C36)
A7: Date | B7: MOMCRUID BUCKET | C7: Sum of FoodBucket | D7: Sum of Housingbucket | E7: Sum of Pantobaccobuckets | F7: Sum of Clothing and footwearbucket | G7: Mom Oils and fatsBuckets | H7: Sum of MiscellaneousBucket
A8: 44197
A9: 44228 | B9: 0.039215686 | C9: -0.022783017 | D9: 0.013316424 | E9: 0.0092378753 | F9: 0.0099082569 | G9: 0.0518008 | H9: 0.0088903523
A10: 44256 | B10: 0.037735849 | C10: -0.0028988069 | D10: 0.00062578223 | E10: -0.00070410139 | F10: 0.0039244186 | G10: 0.032551258 | H10: 0.013225771
A11: 44287 | B11: 0.090909091 | C11: 0.0098207796 | D11: 0.009380863 | E11: 0.0040514356 | F11: 0.0054292746 | G11: 0.037256909 | H11: 0.017341675
A12: 44317 | B12: 0.05 | C12: 0.017080664 | D12: 0.0012391574 | E12: 0.017017544 | F12: 0.019151847 | G12: 0.04973357 | H12: 0.03383273
A13: 44348 | B13: 0.11111111 | C13: 0.01218544 | D13: -0.0068069307 | E13: -0.0072451268 | F13: 0.0011303426 | G13: 0.027072758 | H13: 0.037015695
A14: 44378 | B14: 0.028571429 | C14: 0.0077416274 | D14: 0.0062305296 | E14: 0.0015638575 | F14: 0.0055747654 | G14: -0.0089694307 | H14: 0.04535726
A15: 44409 | B15: 0.027777778 | C15: -0.0055839453 | D15: 0.0037151703 | E15: 0.0041637752 | F15: 0.010245614 | G15: 0.02308829 | H15: 0.051613434
A16: 44440 | B16: -0.013513514 | C16: -0.00030628914 | D16: 0 | E16: 0.00051831375 | F16: 0.0019449847 | G16: 0.0083047481 | H16: 0.052957963
A17: 44470 | B17: 0.095890411 | C17: 0.01652766 | D17: 0.0092535472 | E17: 0.0031082715 | F17: 0.0065169163 | G17: 0.013428827 | H17: 0.060640983
A18: 44501 | B18: 0.025 | C18: 0.0096448485 | D18: 0.0036674817 | E18: 0.00068858668 | F18: 0.0083344813 | G18: -0.0030035336 | H18: 0.064098343
A19: 44531 | B19: -0.085365854 | C19: -0.0051743868 | D19: -0.0048721072 | E19: -0.0022363668 | F19: 0.0077191065 | G19: -0.013113592 | H19: 0.066979475
A20: 44562 | B20: 0.10666667 | C20: -0.0071517879 | D20: 0.0067319461 | E20: -0.0012068966 | F20: 0.0098291757 | G20: -0.015442629 | H20: 0.069723411
... A36: 45047 | B36: -0.027027027 | C36: 0.010315439 | D36: 0.002283105 | E36: 0.0024850895 | F36: 0.0025491624 | G36: -0.027580923 | H36: 0.16197454
B37: Food Buckets | C37: value of Corelations
B38: Cruid Vs Food | C38: =CORREL(B8:B36,C8:C36) -> 0.083001589
B39: Cruid Vs Housing | C39: =CORREL(B8:B36,D8:D36) -> 0.068699644
B40: Cruid Vs Pantobaco | C40: =CORREL(B8:B36,E8:E36) -> 0.0448967
B41: Cruid Vs Clothing footwear | C41: =CORREL(B8:B36,F8:F36) -> 0.18123537
B42: Cruid Vs Oil and Fats | C42: =CORREL(B8:B36,G8:G36) -> 0.59811764
B43: Cruid Vs MiscellaneousBucket | C43: =CORREL(B8:B36,H8:H36) -> -0.53196316
B45: Bucket Comparision | C45: Sum of value of Corelations
B46: oil Vs Clothing footwear | C46: 0.35336706
B47: oil Vs Pantobaco | C47: 0.26289499
B48: oil Vs Food | C48: -0.019465137
B49: oil Vs Housing | C49: -0.063133423
B50: oil Vs MiscellaneousBucket | C50: -0.69187506
A52: Between 2021–2023, imported oil price fluctuations had the greatest positive impact on Clothing & Footwear inflation, while Miscellaneous inflation moved inversely. Food and Housing remained largely unaffected.

Sheet CPIPREVIOUSDATA
A1: Sector | B1: Year | C1: Yearshifted | D1: Month | E1: Cereals and products | F1: Meat and fish | G1: Egg | H1: Milk and products | I1: Oils and fats | J1: Fruits | K1: Vegetables | L1: Pulses and products | M1: Sugar and Confectionery | N1: Spices | O1: Non-alcoholic beverages | P1: Prepared meals, snacks, sweets etc. | Q1: Food and beverages | R1: Pan, tobacco and intoxicants | S1: Clothing | T1: Footwear | U1: Clothing and footwear | V1: Housing | W1: Fuel and light | X1: Household goods and services | Y1: Health | Z1: Transport and communication | AA1: Recreation and amusement | AB1: Education | AC1: Personal care and effects | AD1: Miscellaneous | AE1: previousyearGeneral index
A2: Rural | B2: 2013 | C2: 2014 | D2: january | E2: 107.5 | F2: 106.3 | G2: 108.1 | H2: 104.9 | I2: 106.1 | J2: 103.9 | K2: 101.9 | L2: 106.1 | M2: 106.8 | N2: 103.1 | O2: 104.8 | P2: 106.7 | Q2: 105.5 | R2: 105.1 | S2: 106.5 | T2: 105.8 | U2: 106.4 | V2: 0 | W2: 105.5 | X2: 104.8 | Y2: 104 | Z2: 103.3 | AA2: 103.4 | AB2: 103.8 | AC2: 104.7 | AD2: 104 | AE2: 105.1
A3: Urban | B3: 2013 | C3: 2014 | D3: january | E3: 110.5 | F3: 109.1 | G3: 113 | H3: 103.6 | I3: 103.4 | J3: 102.3 | K3: 102.9 | L3: 105.8 | M3: 105.1 | N3: 101.8 | O3: 105.1 | P3: 107.9 | Q3: 105.9 | R3: 105.2 | S3: 105.9 | T3: 105 | U3: 105.8 | V3: 100.3 | W3: 105.4 | X3: 104.8 | Y3: 104.1 | Z3: 103.2 | AA3: 102.9 | AB3: 103.5 | AC3: 104.3 | AD3: 103.7 | AE3: 104
A4: Rural+Urban | B4: 2013 | C4: 2014 | D4: january | E4: 108.4 | F4: 107.3 | G4: 110 | H4: 104.4 | I4: 105.1 | J4: 103.2 | K4: 102.2 | L4: 106 | M4: 106.2 | N4: 102.7 | O4: 104.9 | P4: 107.3 | Q4: 105.6 | R4: 105.1 | S4: 106.3 | T4: 105.5 | U4: 106.2 | V4: 100.3 | W4: 105.5 | X4: 104.8 | Y4: 104 | Z4: 103.2 | AA4: 103.1 | AB4: 103.6 | AC4: 104.5 | AD4: 103.9 | AE4: 104.6
A5: Rural | B5: 2013 | C5: 2014 | D5: february | E5: 109.2 | F5: 108.7 | G5: 110.2 | H5: 105.4 | I5: 106.7 | J5: 104 | K5: 102.4 | L5: 105.9 | M5: 105.7 | N5: 103.1 | O5: 105.1 | P5: 107.7 | Q5: 106.3 | R5: 105.6 | S5: 107.1 | T5: 106.3 | U5: 107 | V5: 0 | W5: 106.2 | X5: 105.2 | Y5: 104.4 | Z5: 103.9 | AA5: 104 | AB5: 104.1 | AC5: 104.6 | AD5: 104.4 | AE5: 105.8
A6: Urban | B6: 2013 | C6: 2014 | D6: february | E6: 112.9 | F6: 112.9 | G6: 116.9 | H6: 104 | I6: 103.5 | J6: 103.1 | K6: 104.9 | L6: 104.1 | M6: 103.8 | N6: 102.3 | O6: 106 | P6: 109 | Q6: 107.2 | R6: 106 | S6: 106.6 | T6: 105.5 | U6: 106.4 | V6: 100.4 | W6: 105.7 | X6: 105.2 | Y6: 104.7 | Z6: 104.4 | AA6: 103.3 | AB6: 103.7 | AC6: 104.3 | AD6: 104.3 | AE6: 104.7
A7: Rural+Urban | B7: 2013 | C7: 2014 | D7: february | E7: 110.4 | F7: 110.2 | G7: 112.8 | H7: 104.9 | I7: 105.5 | J7: 103.6 | K7: 103.2 | L7: 105.3 | M7: 105.1 | N7: 102.8 | O7: 105.5 | P7: 108.3 | Q7: 106.6 | R7: 105.7 | S7: 106.9 | T7: 106 | U7: 106.8 | V7: 100.4 | W7: 106 | X7: 105.2 | Y7: 104.5 | Z7: 104.2 | AA7: 103.6 | AB7: 103.9 | AC7: 104.5 | AD7: 104.4 | AE7: 105.3
A8: Rural | B8: 2013 | C8: 2014 | D8: march | E8: 110.2 | F8: 108.8 | G8: 109.9 | H8: 105.6 | I8: 106.2 | J8: 105.7 | K8: 101.4 | L8: 105.7 | M8: 105 | N8: 103.3 | O8: 105.6 | P8: 108.2 | Q8: 106.6 | R8: 106.5 | S8: 107.6 | T8: 106.8 | U8: 107.5 | V8: 0 | W8: 106.1 | X8: 105.6 | Y8: 104.7 | Z8: 104.6 | AA8: 104 | AB8: 104.3 | AC8: 104.3 | AD8: 104.6 | AE8: 106
A9: Urban | B9: 2013 | C9: 2014 | D9: march | E9: 113.9 | F9: 111.4 | G9: 113.2 | H9: 104.3 | I9: 102.7 | J9: 104.9 | K9: 103.8 | L9: 103.5 | M9: 102.6 | N9: 102.4 | O9: 107 | P9: 109.8 | Q9: 107.3 | R9: 106.8 | S9: 107.2 | T9: 106 | U9: 107 | V9: 100.4 | W9: 106 | X9: 105.7 | Y9: 105.2 | Z9: 105.5 | AA9: 103.5 | AB9: 103.8 | AC9: 104.2 | AD9: 104.9 | AE9: 105
A10: Rural+Urban | B10: 2013 | C10: 2014 | D10: march | E10: 111.4 | F10: 109.7 | G10: 111.2 | H10: 105.1 | I10: 104.9 | J10: 105.3 | K10: 102.2 | L10: 105 | M10: 104.2 | N10: 103 | O10: 106.2 | P10: 108.9 | Q10: 106.9 | R10: 106.6 | S10: 107.4 | T10: 106.5 | U10: 107.3 | V10: 100.4 | W10: 106.1 | X10: 105.6 | Y10: 104.9 | Z10: 105.1 | AA10: 103.7 | AB10: 104 | AC10: 104.3 | AD10: 104.7 | AE10: 105.5
A11: Rural | B11: 2013 | C11: 2014 | D11: april | E11: 110.2 | F11: 109.5 | G11: 106.9 | H11: 106.3 | I11: 105.7 | J11: 108.3 | K11: 103.4 | L11: 105.7 | M11: 104.2 | N11: 103.2 | O11: 106.5 | P11: 108.8 | Q11: 107.1 | R11: 107.1 | S11: 108.1 | T11: 107.4 | U11: 108 | V11: 0 | W11: 106.5 | X11: 106.1 | Y11: 105.1 | Z11: 104.4 | AA11: 104.5 | AB11: 104.8 | AC11: 102.7 | AD11: 104.6 | AE11: 106.4
A12: Urban | B12: 2013 | C12: 2014 | D12: april | E12: 114.6 | F12: 113.4 | G12: 106 | H12: 104.7 | I12: 102.1 | J12: 109.5 | K12: 109.7 | L12: 104.6 | M12: 102 | N12: 103.5 | O12: 108.2 | P12: 110.6 | Q12: 108.8 | R12: 108.5 | S12: 107.9 | T12: 106.4 | U12: 107.7 | V12: 100.5 | W12: 106.4 | X12: 106.5 | Y12: 105.7 | Z12: 105 | AA12: 104 | AB12: 105.2 | AC12: 103.2 | AD12: 105.1 | AE12: 105.7
A13: Rural+Urban | B13: 2013 | C13: 2014 | D13: april | E13: 111.6 | F13: 110.9 | G13: 106.6 | H13: 105.7 | I13: 104.4 | J13: 108.9 | K13: 105.5 | L13: 105.3 | M13: 103.5 | N13: 103.3 | O13: 107.2 | P13: 109.6 | Q13: 107.7 | R13: 107.5 | S13: 108 | T13: 107 | U13: 107.9 | V13: 100.5 | W13: 106.5 | X13: 106.3 | Y13: 105.3 | Z13: 104.7 | AA13: 104.2 | AB13: 105 | AC13: 102.9 | AD13: 104.8 | AE13: 106.1
... A262: Rural+Urban | B262: 2020 | C262: 2021 | D262: april | E262: 148.7 | F262: 0 | G262: 148.8 | H262: 155.6 | I262: 135.1 | J262: 149.9 | K262: 168.6 | L262: 150.4 | M262: 120.3 | N262: 157.1 | O262: 136.8 | P262: 0 | Q262: 151.4 | R262: 0 | S262: 0 | T262: 0 | U262: 0 | V262: 155.6 | W262: 144.1 | X262: 0 | Y262: 150.7 | Z262: 0 | AA262: 0 | AB262: 0 | AC262: 0 | AD262: 0 | AE262: 0
A263: Rural | B263: 2020 | C263: 2021 | D263: may | E263: 0 | F263: 0 | G263: 0 | H263: 0 | I263: 0 | J263: 0 | K263: 0 | M263: 0 | N263: 0 | O263: 0 | P263: 0 | Q263: 0 | R263: 0 | S263: 0 | T263: 0 | U263: 0 | V263: 0 | W263: 0 | X263: 0 | Y263: 0 | Z263: 0 | AA263: 0 | AB263: 0 | AC263: 0 | AD263: 0 | AE263: 0
A264: Urban | B264: 2020 | C264: 2021 | D264: may | E264: 0 | F264: 0 | G264: 0 | H264: 0 | I264: 0 | J264: 0 | K264: 0 | M264: 0 | N264: 0 | O264: 0 | P264: 0 | Q264: 0 | R264: 0 | S264: 0 | T264: 0 | U264: 0 | V264: 0 | W264: 0 | X264: 0 | Y264: 0 | Z264: 0 | AA264: 0 | AB264: 0 | AC264: 0 | AD264: 0 | AE264: 0
A265: Rural+Urban | B265: 2020 | C265: 2021 | D265: may | E265: 0 | F265: 0 | G265: 0 | H265: 0 | I265: 0 | J265: 0 | K265: 0 | M265: 0 | N265: 0 | O265: 0 | P265: 0 | Q265: 0 | R265: 0 | S265: 0 | T265: 0 | U265: 0 | V265: 0 | W265: 0 | X265: 0 | Y265: 0 | Z265: 0 | AA265: 0 | AB265: 0 | AC265: 0 | AD265: 0 | AE265: 0
A266: Rural | B266: 2020 | C266: 2021 | D266: june | E266: 148.2 | F266: 190.3 | G266: 149.4 | H266: 153.3 | I266: 138.2 | J266: 143.2 | K266: 148.9 | L266: 150.3 | M266: 113.2 | N266: 159.8 | O266: 142.1 | P266: 161.8 | Q266: 152.3 | R266: 182.4 | S266: 154.7 | T266: 150 | U266: 154.1 | V266: 0 | W266: 144.9 | X266: 151.7 | Y266: 158.2 | Z266: 141.4 | AA266: 153.2 | AB266: 161.8 | AC266: 151.2 | AD266: 151.7 | AE266: 152.7
A267: Urban | B267: 2020 | C267: 2021 | D267: june | E267: 152.7 | F267: 197 | G267: 154.6 | H267: 153.4 | I267: 132.9 | J267: 151.8 | K267: 171.2 | L267: 152 | M267: 116.3 | N267: 158.8 | O267: 135.6 | P267: 161.7 | Q267: 157 | R267: 186.7 | S267: 149.1 | T267: 136.6 | U267: 147.2 | V267: 154.7 | W267: 137.1 | X267: 140.4 | Y267: 148.1 | Z267: 129.3 | AA267: 144.5 | AB267: 152.5 | AC267: 152.2 | AD267: 142 | AE267: 150.8
A268: Rural+Urban | B268: 2020 | C268: 2021 | D268: june | E268: 149.6 | F268: 192.7 | G268: 151.4 | H268: 153.3 | I268: 136.3 | J268: 147.2 | K268: 156.5 | L268: 150.9 | M268: 114.2 | N268: 159.5 | O268: 139.4 | P268: 161.8 | Q268: 154 | R268: 183.5 | S268: 152.5 | T268: 144.4 | U268: 151.4 | V268: 154.7 | W268: 141.9 | X268: 146.4 | Y268: 154.4 | Z268: 135 | AA268: 148.3 | AB268: 156.4 | AC268: 151.6 | AD268: 147 | AE268: 151.8
A269: Rural | B269: 2020 | C269: 2021 | D269: july | E269: 148.2 | F269: 190.3 | G269: 149.4 | H269: 153.3 | I269: 138.2 | J269: 143.2 | K269: 148.9 | L269: 150.3 | M269: 113.2 | N269: 159.8 | O269: 142.1 | P269: 161.8 | Q269: 152.3 | R269: 182.4 | S269: 154.7 | T269: 150 | U269: 154.1 | V269: 0 | W269: 144.9 | X269: 151.7 | Y269: 158.2 | Z269: 141.4 | AA269: 153.2 | AB269: 161.8 | AC269: 151.2 | AD269: 151.7 | AE269: 152.7
A270: Urban | B270: 2020 | C270: 2021 | D270: july | E270: 152.7 | F270: 197 | G270: 154.6 | H270: 153.4 | I270: 132.9 | J270: 151.8 | K270: 171.2 | L270: 152 | M270: 116.3 | N270: 158.8 | O270: 135.6 | P270: 161.7 | Q270: 157 | R270: 186.7 | S270: 149.1 | T270: 136.6 | U270: 147.2 | V270: 154.7 | W270: 137.1 | X270: 140.4 | Y270: 148.1 | Z270: 129.3 | AA270: 144.5 | AB270: 152.5 | AC270: 152.2 | AD270: 142 | AE270: 150.8
A271: Rural+Urban | B271: 2020 | C271: 2021 | D271: july | E271: 149.6 | F271: 192.7 | G271: 151.4 | H271: 153.3 | I271: 136.3 | J271: 147.2 | K271: 156.5 | L271: 150.9 | M271: 114.2 | N271: 159.5 | O271: 139.4 | P271: 161.8 | Q271: 154 | R271: 183.5 | S271: 152.5 | T271: 144.4 | U271: 151.4 | V271: 154.7 | W271: 141.9 | X271: 146.4 | Y271: 154.4 | Z271: 135 | AA271: 148.3 | AB271: 156.4 | AC271: 151.6 | AD271: 147 | AE271: 151.8
A272: Rural | B272: 2020 | C272: 2021 | D272: august | E272: 147.6 | F272: 187.2 | G272: 148.4 | H272: 153.3 | I272: 139.8 | J272: 146.9 | K272: 171 | L272: 149.9 | M272: 114.2 | N272: 160 | O272: 143.5 | P272: 161.5 | Q272: 155.3 | R272: 180.9 | S272: 155.1 | T272: 149.3 | U272: 154.3 | V272: 0 | W272: 145.8 | X272: 151.9 | Y272: 158.8 | Z272: 143.6 | AA272: 152.2 | AB272: 162.7 | AC272: 153.6 | AD272: 153 | AE272: 154.7
A273: Urban | B273: 2020 | C273: 2021 | D273: august | E273: 151.6 | F273: 197.8 | G273: 154.5 | H273: 153.4 | I273: 133.4 | J273: 154.5 | K273: 191.9 | L273: 151.3 | M273: 116.8 | N273: 160 | O273: 136.5 | P273: 163.3 | Q273: 159.9 | R273: 187.2 | S273: 150 | T273: 135.2 | U273: 147.8 | V273: 155.5 | W273: 138.3 | X273: 144.5 | Y273: 148.7 | Z273: 133.9 | AA273: 141.2 | AB273: 155.5 | AC273: 155.2 | AD273: 144.8 | AE273: 152.9
A274: Rural+Urban | B274: 2020 | C274: 2021 | D274: august | E274: 148.9 | F274: 190.9 | G274: 150.8 | H274: 153.3 | I274: 137.4 | J274: 150.4 | K274: 178.1 | L274: 150.4 | M274: 115.1 | N274: 160 | O274: 140.6 | P274: 162.3 | Q274: 157 | R274: 182.6 | S274: 153.1 | T274: 143.4 | U274: 151.7 | V274: 155.5 | W274: 143 | X274: 148.4 | Y274: 155 | Z274: 138.5 | AA274: 146 | AB274: 158.5 | AC274: 154.3 | AD274: 149 | AE274: 153.9
A275: Rural | B275: 2020 | C275: 2021 | D275: september | E275: 146.9 | F275: 183.9 | G275: 149.5 | H275: 153.4 | I275: 140.4 | J275: 147 | K275: 178.8 | L275: 149.3 | M275: 115.1 | N275: 160 | O275: 145.4 | P275: 161.6 | Q275: 156.1 | R275: 182.9 | S275: 155.4 | T275: 149.9 | U275: 154.6 | V275: 0 | W275: 146.4 | X275: 151.6 | Y275: 159.1 | Z275: 144.6 | AA275: 152.8 | AB275: 161.1 | AC275: 157.4 | AD275: 153.7 | AE275: 155.4
A276: Urban | B276: 2020 | C276: 2021 | D276: september | E276: 151.5 | F276: 193.1 | G276: 157.3 | H276: 153.9 | I276: 134.4 | J276: 155.4 | K276: 202 | L276: 150.8 | M276: 118.9 | N276: 160.9 | O276: 137.7 | P276: 164.4 | Q276: 161.3 | R276: 188.7 | S276: 150.2 | T276: 136.3 | U276: 148.1 | V276: 156.3 | W276: 137.2 | X276: 145.4 | Y276: 150 | Z276: 135.1 | AA276: 141.8 | AB276: 154.9 | AC276: 159.8 | AD276: 146 | AE276: 154
A277: Rural+Urban | B277: 2020 | C277: 2021 | D277: september | E277: 148.4 | F277: 187.1 | G277: 152.5 | H277: 153.6 | I277: 138.2 | J277: 150.9 | K277: 186.7 | L277: 149.8 | M277: 116.4 | N277: 160.3 | O277: 142.2 | P277: 162.9 | Q277: 158 | R277: 184.4 | S277: 153.4 | T277: 144.3 | U277: 152 | V277: 156.3 | W277: 142.9 | X277: 148.7 | Y277: 155.6 | Z277: 139.6 | AA277: 146.6 | AB277: 157.5 | AC277: 158.4 | AD277: 150 | AE277: 154.7
... A373: Rural+Urban | B373: 2023 | C373: 2024 | D373: may | E373: 173.7 | F373: 214.3 | G373: 173.2 | H373: 179.5 | I373: 170 | J373: 172.2 | K373: 161 | L373: 175.6 | M373: 122.7 | N373: 218 | O373: 173.4 | P373: 194.2 | Q373: 179.1 | R373: 201 | S373: 187.3 | T373: 179.7 | U373: 186.2 | V373: 175.6 | W373: 182.8 | X373: 175.2 | Y373: 185.7 | Z373: 164.8 | AA373: 171.2 | AB373: 177.1 | AC373: 185.2 | AD373: 175.7 | AE373: 179.1
